Workbook

Sheet Feature Register
A1: Component ID | B1: L1 Domain | C1: Module | D1: Submodule | E1: Function / Workflow | F1: Artifact Type | G1: Arabic / RTL | H1: Priority | I1: Sequence | J1: EGY Market applicability | K1: KSA Market applicability | L1: Recommended Action | M1: Status | N1: Owner | O1: Target Release | P1: Notes | Q1: Current Capability | R1: UI/UX Score (1–5) | S1: Functional Fit (1–5) | T1: Effort (days) | U1: Odoo Equivalent | V1: Odoo Parity | W1: Gap vs Odoo | X1: Code Reference
A2: FIN001 | B2: Financial | C2: GL | D2: Chart of Accounts | E2: Global chart of accounts maintenance | F2: Screen | G2: Partial | H2: High | I2: 1 | M2: Completed | Q2: Create/update GL accounts, classes, types, sub-classes; hierarchical COA with course labels | R2: 3 | S2: 4 | U2: account.account | V2: At Parity | X2: Application/Accounting/GlobalGlSettings/
A3: FIN002 | B3: Financial | C3: GL | D3: Chart of Accounts | E3: GL account hierarchy and sub-class navigation | F3: Screen | G3: Partial | H3: Medium | I3: 2 | M3: Completed | Q3: GetGlAccountHierarchy + GetGlSubClasses drive a true parent/child tree | R3: 3 | S3: 5 | U3: account.group | V3: Ahead | W3: Odoo account groups are a flat prefix convention; this is a real hierarchy | X3: Application/Accounting/OrganizationGlSettings/
A4: FIN003 | B4: Financial | C4: GL | D4: Chart of Accounts | E4: Organization-level COA assignment | F4: Screen | G4: Partial | H4: High | I4: 3 | M4: Completed | Q4: Assign/remove GL accounts per internal organization, bulk property update | R4: 3 | S4: 4 | U4: multi-company COA | V4: At Parity | X4: Application/Accounting/OrganizationGlSettings/AssignGlAccountToOrganization.cs
A5: FIN004 | B5: Financial | C5: GL | D5: Configuration | E5: GL account type defaults | F5: Configuration | G5: Partial | H5: Medium | I5: 4 | M5: Completed | Q5: ListGlAccountTypeDefaults / RemoveGlAccountTypeDefault per organization | R5: 3 | S5: 4 | U5: journal + product category default accounts | V5: At Parity | X5: Application/Accounting/OrganizationGlSettings/
A6: FIN005 | B6: Financial | C6: GL | D6: Configuration | E6: Party / product / category GL overrides | F6: Configuration | G6: Partial | H6: Medium | I6: 5 | M6: Completed | Q6: Per-party, per-product, per-category, per-fin-account-type, per-fixed-asset-type, per-variance-reason GL mapping | R6: 3 | S6: 5 | U6: property fields on partner/product | V6: Ahead | W6: Odoo maps at fewer dimensions out of the box | X6: Application/Accounting/OrganizationGlSettings/
A7: FIN006 | B7: Financial | C7: GL | D7: Journal Entries | E7: Manual accounting transaction entry | F7: Screen | G7: Partial | H7: High | I7: 6 | M7: Completed | Q7: CreateAcctgTrans + CreateAcctgTransEntry, plus QuickCreateAcctgTrans | R7: 3 | S7: 4 | U7: account.move / account.move.line | V7: At Parity | X7: Application/Accounting/Transactions/
A8: FIN007 | B8: Financial | C8: GL | D8: Journal Entries | E8: Post / unpost transactions | F8: Workflow | G8: Partial | H8: High | I8: 7 | M8: Completed | Q8: PostAcctgTrans, UnpostAcctgTrans, CompleteAcctgTransEntries | R8: 3 | S8: 4 | U8: post / reset to draft | V8: At Parity | X8: Application/Accounting/Transactions/PostAcctgTrans.cs
A9: FIN008 | B9: Financial | C9: GL | D9: Journal Entries | E9: Multi-line journal create and update | F9: Screen | G9: Partial | H9: High | I9: 8 | M9: Completed | Q9: CreateMultiAcctgTransWithEntries / UpdateMultiAcctgTransWithEntries | R9: 3 | S9: 4 | U9: account.move form | V9: At Parity | X9: Application/Accounting/Transactions/
A10: FIN009 | B10: Financial | C10: GL | D10: Journal Entries | E10: Duplicate transaction | F10: Screen | G10: Partial | H10: Low | I10: 9 | M10: Completed | Q10: DuplicateAcctgTrans | R10: 3 | S10: 4 | U10: duplicate action | V10: At Parity | X10: Application/Accounting/Transactions/DuplicateAcctgTrans.cs
A11: FIN010 | B11: Financial | C11: GL | D11: Journal Entries | E11: Opening / initial balance transactions | F11: Batch | G11: Partial | H11: Medium | I11: 10 | M11: Completed | Q11: CreateInitialBalanceTrans | R11: 3 | S11: 4 | U11: opening balance wizard | V11: At Parity | X11: Application/Accounting/Transactions/CreateInitialBalanceTrans.cs
A12: FIN011 | B12: Financial | C12: GL | D12: Journal Entries | E12: Transaction listing and drill-down by date range | F12: Screen | G12: Partial | H12: High | I12: 11 | M12: Completed | Q12: ListAccountingTransactions, ...ByDateRange, per-invoice / per-payment / per-work-effort entry views | R12: 3 | S12: 4 | U12: journal items list | V12: At Parity | X12: Application/Accounting/Transactions/
A13: FIN012 | B13: Financial | C13: GL | D13: Period Close | E13: Financial time period close | F13: Workflow | G13: Partial | H13: High | I13: 12 | L13: Add hard lock dates and a re-open audit trail | M13: Completed | Q13: CloseFinancialTimePeriod + custom time period maintenance | R13: 3 | S13: 2 | T13: 10 | U13: fiscal year + lock dates | V13: Behind | W13: Odoo enforces separate journal / tax / all-user lock dates that block posting; close here is advisory | X13: Application/Accounting/OrganizationGlSettings/CloseFinancialTimePeriod.cs
A14: FIN013 | B14: Financial | C14: GL | D14: Reporting | E14: Trial balance report | F14: Report | G14: Partial | H14: High | I14: 13 | M14: Completed | Q14: GetTrialBalanceReport + GetGlAccountTrialBalanceReport | R14: 3 | S14: 4 | U14: Trial Balance | V14: At Parity | X14: Application/Accounting/OrganizationGlSettings/
A15: FIN014 | B15: Financial | C15: GL | D15: Reporting | E15: Balance sheet and comparative balance sheet | F15: Report | G15: Partial | H15: High | I15: 14 | M15: Completed | Q15: GetBalanceSheetReport, GenerateComparativeBalanceSheet, ComparativeBalanceTotal | R15: 3 | S15: 4 | U15: Balance Sheet | V15: At Parity | X15: Application/Accounting/OrganizationGlSettings/
A16: FIN015 | B16: Financial | C16: GL | D16: Reporting | E16: Income statement and comparative | F16: Report | G16: Partial | H16: High | I16: 15 | M16: Completed | Q16: GetIncomeStatementReport + GetComparativeIncomeStatementReport | R16: 3 | S16: 4 | U16: Profit and Loss | V16: At Parity | X16: Application/Accounting/OrganizationGlSettings/
A17: FIN016 | B17: Financial | C17: GL | D17: Reporting | E17: Cash flow statement | F17: Report | G17: Partial | H17: Medium | I17: 16 | M17: Completed | Q17: GetCashFlowStatementReport | R17: 3 | S17: 4 | U17: Cash Flow Statement | V17: At Parity | X17: Application/Accounting/OrganizationGlSettings/GetCashFlowStatementReport.cs
A18: FIN017 | B18: Financial | C18: GL | D18: Reporting | E18: Transaction totals report | F18: Report | G18: Partial | H18: Medium | I18: 17 | M18: Completed | Q18: GetTransactionTotalsReport | R18: 3 | S18: 4 | U18: journal audit report | V18: At Parity | X18: Application/Accounting/OrganizationGlSettings/
A19: FIN018 | B19: Financial | C19: GL | D19: Reporting | E19: Inventory valuation report | F19: Report | G19: Partial | H19: High | I19: 18 | M19: Completed | Q19: GetInventoryValuationReport | R19: 3 | S19: 4 | U19: stock valuation report | V19: At Parity | X19: Application/Accounting/OrganizationGlSettings/GetInventoryValuationReport.cs
A20: FIN019 | B20: Financial | C20: GL | D20: Reporting | E20: GL account transaction detail drill-down | F20: Report | G20: Partial | H20: High | I20: 19 | M20: Completed | Q20: Balance-sheet and income-statement drill-through to underlying entries | R20: 3 | S20: 4 | U20: report drill-down | V20: At Parity | X20: Application/Accounting/OrganizationGlSettings/
A21: FIN020 | B21: Financial | C21: GL | D21: Reporting | E21: Party financial history and sub-ledger | F21: Report | G21: Partial | H21: High | I21: 20 | M21: Completed | Q21: GetPartyFinancialHistory + GetPartySubLedgerDetails | R21: 3 | S21: 4 | U21: Partner Ledger | V21: At Parity | X21: Application/Accounting/Services/
A22: FIN021 | B22: Financial | C22: GL | D22: Reporting | E22: GL account diagram | F22: Screen | G22: Partial | H22: Low | I22: 21 | M22: Completed | Q22: GetGlAccountDiagramQueryHandler renders account relationships visually | R22: 3 | S22: 5 | U22: none | V22: Ahead | W22: No Odoo equivalent | X22: Application/Accounting/Services/GetGlAccountDiagramQueryHandler.cs
A23: FIN022 | B23: Financial | C23: GL | D23: Reporting | E23: Company report | F23: Report | G23: Partial | H23: Medium | I23: 22 | M23: Completed | Q23: GetCompanyReport | R23: 3 | S23: 4 | U23: company overview | V23: At Parity | X23: Application/Accounting/Reports/GetCompanyReport.cs
A24: FIN023 | B24: Financial | C24: GL | D24: Reporting | E24: Aged receivable / payable ageing report | F24: Report | G24: Partial | H24: High | I24: 23 | L24: Build from existing sub-ledger data | M24: Planned | Q24: Partially served by party financial history; no dedicated ageing buckets | R24: 3 | S24: 2 | T24: 8 | U24: Aged Receivable / Aged Payable | V24: Behind | W24: Odoo ships bucketed ageing with drill-down and PDF/XLSX export
A25: FIN024 | B25: Financial | C25: GL | D25: Reporting | E25: Budget vs actual | F25: Report | G25: Not Applicable | H25: Medium | I25: 24 | L25: Track E dependency - needs a charting layer first | M25: Planned | Q25: No budgeting entity or report | S25: 1 | T25: 20 | U25: account_budget | V25: Gap - not built | W25: Referenced as FIN-BUD in the ERPv2 five-track plan
A26: FIN025 | B26: Financial | C26: AR | D26: Invoice Processing | E26: Sales invoice entry | F26: Screen | G26: Partial | H26: High | I26: 25 | M26: Completed | Q26: CreateInvoice, CreateInvoiceItem, UpdateInvoice, UpdateInvoiceItem | R26: 3 | S26: 4 | U26: account.move (out_invoice) | V26: At Parity | X26: Application/Accounting/Invoices/
A27: FIN026 | B27: Financial | C27: AP | D27: Invoice Processing | E27: Purchase invoice entry | F27: Screen | G27: Partial | H27: High | I27: 26 | M27: Completed | Q27: Same handler set driven by invoice type | R27: 3 | S27: 4 | U27: account.move (in_invoice) | V27: At Parity | X27: Application/Accounting/Invoices/
A28: FIN027 | B28: Financial | C28: AR | D28: Invoice Processing | E28: Invoice item maintenance | F28: Screen | G28: Partial | H28: High | I28: 27 | M28: Completed | Q28: CreateInvoiceItem / UpdateInvoiceItem / DeleteInvoiceItem | R28: 3 | S28: 4 | U28: invoice lines | V28: At Parity | X28: Application/Accounting/Invoices/
A29: FIN028 | B29: Financial | C29: AR | D29: Invoice Processing | E29: Invoice status workflow | F29: Workflow | G29: Partial | H29: High | I29: 28 | M29: Completed | Q29: ChangeInvoiceStatus + ResetInvoice | R29: 3 | S29: 4 | U29: draft / posted / cancel | V29: At Parity | X29: Application/Accounting/Invoices/ChangeInvoiceStatus.cs
A30: FIN029 | B30: Financial | C30: AR | D30: Invoice Processing | E30: Invoice total calculation | F30: API | G30: Partial | H30: High | I30: 29 | M30: Completed | Q30: CalculateInvoiceTotal | R30: 3 | S30: 4 | U30: computed totals | V30: At Parity | X30: Application/Accounting/Invoices/CalculateInvoiceTotal.cs
A31: FIN030 | B31: Financial | C31: AR | D31: Invoice Processing | E31: Invoice listing and search | F31: Screen | G31: Partial | H31: High | I31: 30 | M31: Completed | Q31: ListInvoices, ListInvoice, ListNotAppliedInvoices | R31: 3 | S31: 4 | U31: invoice list views | V31: At Parity | X31: Application/Accounting/Invoices/
A32: FIN031 | B32: Financial | C32: AR | D32: Invoice Processing | E32: Invoice generation from shipments | F32: Batch | G32: Partial | H32: Medium | I32: 31 | M32: Completed | Q32: CreateInvoicesFromShipments | R32: 3 | S32: 4 | U32: invoice from delivery | V32: At Parity | X32: Application/Accounting/Invoices/
A33: FIN032 | B33: Financial | C33: AP | D33: Payroll | E33: Payroll invoice batch creation | F33: Batch | G33: Partial | H33: High | I33: 32 | M33: Completed | Q33: BatchCreatePayrollInvoices, CheckExistingPayrollInvoices, DeletePayrollInvoices, ListPayrollData2 | R33: 3 | S33: 5 | U33: hr_payroll (separate app) | V33: Ahead | W33: Payroll posts straight to AP invoices here; net is rounded per invoice to 2dp then summed | X33: Application/Accounting/Invoices/BatchCreatePayrollInvoices.cs
A34: FIN033 | B34: Financial | C34: AP | D34: Invoice Processing | E34: Supply certificate accounting remediation | F34: Batch | G34: Partial | H34: Low | I34: 33 | M34: Completed | Q34: RemediateSupplyCertificateAccounting + RemediateSupplyCertificateDuplicateAp | R34: 3 | S34: 5 | U34: none | V34: Ahead | W34: Data-repair tooling for a project-specific posting defect | X34: Application/Accounting/Invoices/
A35: FIN034 | B35: Financial | C35: AR | D35: Compliance | E35: e-Invoicing - ZATCA (KSA) | F35: API | G35: Not Applicable | H35: High | I35: 34 | J35: Not Applicable | K35: Non-Compliant | L35: Required before any KSA deployment | M35: Planned | Q35: Nothing built | S35: 1 | T35: 45 | U35: l10n_sa_edi | V35: Gap - not built | W35: Phase 2 ZATCA clearance, XML/UBL, QR, CSID onboarding all absent
A36: FIN035 | B36: Financial | C36: AR | D36: Compliance | E36: e-Invoicing - Egypt ETA | F36: API | G36: Not Applicable | H36: High | I36: 35 | J36: Non-Compliant | K36: Not Applicable | L36: Required for the EGY market | M36: Planned | Q36: Nothing built | S36: 1 | T36: 35 | U36: l10n_eg_edi_eta | V36: Gap - not built | W36: ETA JSON submission, UUID, signing all absent
A37: FIN036 | B37: Financial | C37: AR | D37: Payment Processing | E37: Incoming payment entry | F37: Screen | G37: Partial | H37: High | I37: 36 | M37: Completed | Q37: CreatePayment + ListIncomingPayments + ListIncomingPaymentTypes | R37: 3 | S37: 4 | U37: account.payment (inbound) | V37: At Parity | X37: Application/Accounting/Payments/
A38: FIN037 | B38: Financial | C38: AP | D38: Payment Processing | E38: Outgoing payment entry | F38: Screen | G38: Partial | H38: High | I38: 37 | M38: Completed | Q38: CreatePayment + ListOutgoingPayments + ListOutgoingPaymentTypes | R38: 3 | S38: 4 | U38: account.payment (outbound) | V38: At Parity | X38: Application/Accounting/Payments/
A39: FIN038 | B39: Financial | C39: AR | D39: Payment Processing | E39: Payment application to invoices | F39: Screen | G39: Partial | H39: High | I39: 38 | M39: Completed | Q39: CreatePaymentApplication, RemovePaymentApplication, ListPaymentsApplicationsForInvoice | R39: 3 | S39: 4 | U39: payment matching | V39: At Parity | X39: Application/Accounting/Payments/
A40: FIN039 | B40: Financial | C40: AR | D40: Payment Processing | E40: Combined payment and application | F40: API | G40: Partial | H40: Medium | I40: 39 | M40: Completed | Q40: CreatePaymentAndApplication + CreatePaymentAndFinAccountTrans | R40: 3 | S40: 4 | U40: register payment wizard | V40: At Parity | X40: Application/Accounting/Payments/
...

Sheet Odoo Gap Summary
A1: Coverage rollup — Contracts ERP vs Odoo
A3: L1 Domain | B3: Ahead | C3: At Parity | D3: Behind | E3: Gap - not built | F3: Total | G3: Build days
A4: Financial | B4: =COUNTIFS('Feature Register'!$B:$B,$A4,'Feature Register'!$V:$V,B$3) | C4: =COUNTIFS('Feature Register'!$B:$B,$A4,'Feature Register'!$V:$V,C$3) | D4: =COUNTIFS('Feature Register'!$B:$B,$A4,'Feature Register'!$V:$V,D$3) | E4: =COUNTIFS('Feature Register'!$B:$B,$A4,'Feature Register'!$V:$V,E$3) | F4: =SUM(B4:E4) | G4: =SUMIF('Feature Register'!$B:$B,$A4,'Feature Register'!$T:$T)
A5: Order Management | B5: =COUNTIFS('Feature Register'!$B:$B,$A5,'Feature Register'!$V:$V,B$3) | C5: =COUNTIFS('Feature Register'!$B:$B,$A5,'Feature Register'!$V:$V,C$3) | D5: =COUNTIFS('Feature Register'!$B:$B,$A5,'Feature Register'!$V:$V,D$3) | E5: =COUNTIFS('Feature Register'!$B:$B,$A5,'Feature Register'!$V:$V,E$3) | F5: =SUM(B5:E5) | G5: =SUMIF('Feature Register'!$B:$B,$A5,'Feature Register'!$T:$T)
A6: Procurement | B6: =COUNTIFS('Feature Register'!$B:$B,$A6,'Feature Register'!$V:$V,B$3) | C6: =COUNTIFS('Feature Register'!$B:$B,$A6,'Feature Register'!$V:$V,C$3) | D6: =COUNTIFS('Feature Register'!$B:$B,$A6,'Feature Register'!$V:$V,D$3) | E6: =COUNTIFS('Feature Register'!$B:$B,$A6,'Feature Register'!$V:$V,E$3) | F6: =SUM(B6:E6) | G6: =SUMIF('Feature Register'!$B:$B,$A6,'Feature Register'!$T:$T)
A7: Inventory | B7: =COUNTIFS('Feature Register'!$B:$B,$A7,'Feature Register'!$V:$V,B$3) | C7: =COUNTIFS('Feature Register'!$B:$B,$A7,'Feature Register'!$V:$V,C$3) | D7: =COUNTIFS('Feature Register'!$B:$B,$A7,'Feature Register'!$V:$V,D$3) | E7: =COUNTIFS('Feature Register'!$B:$B,$A7,'Feature Register'!$V:$V,E$3) | F7: =SUM(B7:E7) | G7: =SUMIF('Feature Register'!$B:$B,$A7,'Feature Register'!$T:$T)
A8: Logistics | B8: =COUNTIFS('Feature Register'!$B:$B,$A8,'Feature Register'!$V:$V,B$3) | C8: =COUNTIFS('Feature Register'!$B:$B,$A8,'Feature Register'!$V:$V,C$3) | D8: =COUNTIFS('Feature Register'!$B:$B,$A8,'Feature Register'!$V:$V,D$3) | E8: =COUNTIFS('Feature Register'!$B:$B,$A8,'Feature Register'!$V:$V,E$3) | F8: =SUM(B8:E8) | G8: =SUMIF('Feature Register'!$B:$B,$A8,'Feature Register'!$T:$T)
A9: Manufacturing | B9: =COUNTIFS('Feature Register'!$B:$B,$A9,'Feature Register'!$V:$V,B$3) | C9: =COUNTIFS('Feature Register'!$B:$B,$A9,'Feature Register'!$V:$V,C$3) | D9: =COUNTIFS('Feature Register'!$B:$B,$A9,'Feature Register'!$V:$V,D$3) | E9: =COUNTIFS('Feature Register'!$B:$B,$A9,'Feature Register'!$V:$V,E$3) | F9: =SUM(B9:E9) | G9: =SUMIF('Feature Register'!$B:$B,$A9,'Feature Register'!$T:$T)
A10: Projects | B10: =COUNTIFS('Feature Register'!$B:$B,$A10,'Feature Register'!$V:$V,B$3) | C10: =COUNTIFS('Feature Register'!$B:$B,$A10,'Feature Register'!$V:$V,C$3) | D10: =COUNTIFS('Feature Register'!$B:$B,$A10,'Feature Register'!$V:$V,D$3) | E10: =COUNTIFS('Feature Register'!$B:$B,$A10,'Feature Register'!$V:$V,E$3) | F10: =SUM(B10:E10) | G10: =SUMIF('Feature Register'!$B:$B,$A10,'Feature Register'!$T:$T)
A11: Catalog | B11: =COUNTIFS('Feature Register'!$B:$B,$A11,'Feature Register'!$V:$V,B$3) | C11: =COUNTIFS('Feature Register'!$B:$B,$A11,'Feature Register'!$V:$V,C$3) | D11: =COUNTIFS('Feature Register'!$B:$B,$A11,'Feature Register'!$V:$V,D$3) | E11: =COUNTIFS('Feature Register'!$B:$B,$A11,'Feature Register'!$V:$V,E$3) | F11: =SUM(B11:E11) | G11: =SUMIF('Feature Register'!$B:$B,$A11,'Feature Register'!$T:$T)
A12: Parties | B12: =COUNTIFS('Feature Register'!$B:$B,$A12,'Feature Register'!$V:$V,B$3) | C12: =COUNTIFS('Feature Register'!$B:$B,$A12,'Feature Register'!$V:$V,C$3) | D12: =COUNTIFS('Feature Register'!$B:$B,$A12,'Feature Register'!$V:$V,D$3) | E12: =COUNTIFS('Feature Register'!$B:$B,$A12,'Feature Register'!$V:$V,E$3) | F12: =SUM(B12:E12) | G12: =SUMIF('Feature Register'!$B:$B,$A12,'Feature Register'!$T:$T)
A13: CRM | B13: =COUNTIFS('Feature Register'!$B:$B,$A13,'Feature Register'!$V:$V,B$3) | C13: =COUNTIFS('Feature Register'!$B:$B,$A13,'Feature Register'!$V:$V,C$3) | D13: =COUNTIFS('Feature Register'!$B:$B,$A13,'Feature Register'!$V:$V,D$3) | E13: =COUNTIFS('Feature Register'!$B:$B,$A13,'Feature Register'!$V:$V,E$3) | F13: =SUM(B13:E13) | G13: =SUMIF('Feature Register'!$B:$B,$A13,'Feature Register'!$T:$T)
A14: Human Resources | B14: =COUNTIFS('Feature Register'!$B:$B,$A14,'Feature Register'!$V:$V,B$3) | C14: =COUNTIFS('Feature Register'!$B:$B,$A14,'Feature Register'!$V:$V,C$3) | D14: =COUNTIFS('Feature Register'!$B:$B,$A14,'Feature Register'!$V:$V,D$3) | E14: =COUNTIFS('Feature Register'!$B:$B,$A14,'Feature Register'!$V:$V,E$3) | F14: =SUM(B14:E14) | G14: =SUMIF('Feature Register'!$B:$B,$A14,'Feature Register'!$T:$T)
A15: Service Center | B15: =COUNTIFS('Feature Register'!$B:$B,$A15,'Feature Register'!$V:$V,B$3) | C15: =COUNTIFS('Feature Register'!$B:$B,$A15,'Feature Register'!$V:$V,C$3) | D15: =COUNTIFS('Feature Register'!$B:$B,$A15,'Feature Register'!$V:$V,D$3) | E15: =COUNTIFS('Feature Register'!$B:$B,$A15,'Feature Register'!$V:$V,E$3) | F15: =SUM(B15:E15) | G15: =SUMIF('Feature Register'!$B:$B,$A15,'Feature Register'!$T:$T)
A16: Platform | B16: =COUNTIFS('Feature Register'!$B:$B,$A16,'Feature Register'!$V:$V,B$3) | C16: =COUNTIFS('Feature Register'!$B:$B,$A16,'Feature Register'!$V:$V,C$3) | D16: =COUNTIFS('Feature Register'!$B:$B,$A16,'Feature Register'!$V:$V,D$3) | E16: =COUNTIFS('Feature Register'!$B:$B,$A16,'Feature Register'!$V:$V,E$3) | F16: =SUM(B16:E16) | G16: =SUMIF('Feature Register'!$B:$B,$A16,'Feature Register'!$T:$T)
A17: TOTAL | B17: =SUM(B4:B16) | C17: =SUM(C4:C16) | D17: =SUM(D4:D16) | E17: =SUM(E4:E16) | F17: =SUM(F4:F16) | G17: =SUM(G4:G16)
A19: Build days = sum of the Effort (days) column, which is populated only on rows carrying a Recommended Action.
A20: Counts are live COUNTIFS against the register — they update when you re-classify a row.

Sheet Legend & Method
A1: Legend and method
A3: Column | B3: How it was derived | C3: Who fills it
A4: Component ID | B4: Assigned per L1 domain: FIN / ORD / PRC / INV / SHP / MFG / PRJ / CAT / PTY / CRM / HCM / SVC / SYS. | C4: Fixed
A5: L1 Domain, Module, Submodule | B5: Derived from the Application/ folder structure and the CQRS handler groupings. | C5: Fixed
A6: Function / Workflow | B6: One row per coherent business function, grouping the handlers that implement it. 265 rows cover 737 operation files. | C6: Fixed
A7: Artifact Type | B7: Screen / Report / API / Batch / Workflow / Mobile / Configuration — judged from the handler set and whether a client screen exists. | C7: Claude — review
A8: Arabic / RTL | B8: MEASURED per feature folder: share of .tsx files calling getTranslatedLabel. Compliant >=85%, Partial 40–85%, Non-Compliant <40%. Applied at module level, so individual screens may differ. | C8: Claude — verify per screen
A9: Priority | B9: Proposed, weighing business criticality against the size of the Odoo gap. | C9: YOU — this is a business call
A10: Sequence | B10: Running order within the L1 domain. Placeholder ordering only. | C10: YOU
A11: EGY / KSA Market applicability | B11: LEFT BLANK except for the three e-invoicing and tax-filing rows. Nothing in the code indicates market applicability. | C11: YOU
A12: Recommended Action | B12: Filled only where a concrete gap or defect was identified. | C12: Claude — review
A13: Status | B13: Completed = implemented and in use. Under Development = exists but with a known material gap. Planned = nothing built. | C13: YOU — reconcile with reality
A14: Owner, Target Release | B14: LEFT BLANK. Assignment and release planning are yours. | C14: YOU
... A22: Code Reference | B22: Path to the folder or file that implements it, so any row can be checked against the source. | C22: Fixed — verifiable
A24: Provenance
A25: Compiled 2026-08-23 from a direct inventory of the working tree, not from estimates or memory.
A26: 737 CQRS operation files across 68 module groups in Application/; 892 Domain entities; 146 API controllers.
A27: Frontend signals measured across 922 .ts/.tsx files in client-app/src.
A28: Odoo comparison is against Odoo 17/18 Community plus the standard Enterprise apps named in the Odoo Equivalent column.
A29: Structure follows the "Z ERP (1).xlsx" template: same first 20 columns and the same dropdown vocabularies, extended with four Odoo columns (U–X).
A30: Companion narrative: ERPv2/ERPv2-Brief.md.
