Workbook

Sheet البنود
A1: م | B1: الصفحة | C1: القسم | D1: رقم البند في الأصل | E1: النص كما كُتب | F1: مصطلح إنجليزي في الأصل | G1: قراءة غير مؤكدة
A2: 1 | B2: 1 | C2: التقارير والنظام عمومًا | D2: — | E2: إنشاء محرك خاص بالتقارير + Custom Report تفصيلي حسب الطلب. | F2: Custom Report
A3: 2 | B3: 1 | C3: التقارير والنظام عمومًا | D3: — | E3: تقارير القسم محتاجة تظبيط ⟨تراكم⟩ الأعمال والميزانية، مع وجود مستويات لعرض التقرير ((Subtotal)). | F3: Subtotal | G3: نعم
A4: 3 | B4: 1 | C4: التقارير والنظام عمومًا | D4: ★ | E4: إضافة أكثر من شركة (جولدن / الأرض القابضة).
A5: 4 | B5: 1 | C5: التقارير والنظام عمومًا | D5: ★ | E5: DMS — ربط ⟨السيستم⟩ بالمستندات المرفقة، مع كل رقم دفعة يتم الوصول إليها بضغط رقم الدفعة. | F5: DMS | G5: نعم
A6: 5 | B6: 1 | C6: التقارير والنظام عمومًا | D6: ★ | E6: PDC Management — ملاحظة هامشية: ⟨شاشة خاصة بالشيكات: استحقاق / الدفع / مرتجع⟩. | F6: PDC Management | G6: نعم
A7: 6 | B7: 1 | C7: التقارير والنظام عمومًا | D7: — | E7: مشاكل التقارير: يضاف زر للطباعة يتم توجيه طباعة التقرير بدون الحاجة إلى التعديلات في الفورمات وحجم الصفحة، زي سند الصرف والقبض.
A8: 7 | B8: 1 | C8: التقارير والنظام عمومًا | D8: — | E8: إضافة شاشة للتحويلات بين الحسابات البنكية والخزينة، مثلًا من CIB إلى ADIB، أو من الخزينة إلى CIB.
A9: 8 | B9: 1 | C9: التقارير والنظام عمومًا | D9: — | E9: أنواع الدفعات محتاجة إعادة تعريف.
A10: 9 | B10: 1 | C10: التقارير والنظام عمومًا | D10: — | E10: إظهار القيود اليومية مدين ودائن في شاشة الصرف والقبض قبل الإنشاء.
A11: 10 | B11: 2 | C11: العرض والطباعة والأتمتة | D11: 1 | E11: إجمالًا طريقة العرض والطباعة محتاجة تحديث لتظهر بصورة احترافية، وكشوفات الحساب ⟨محتاجة⟩ وجميع الأشكال المصدرة محتاجة إعادة فورمات وترتيب الأعمدة لتظهر بشكل ⟨…⟩ كشف حساب البنك، ليتم طباعتها مباشرة دون إجراء تعديلات في كل مرة. | G11: نعم
A12: 11 | B12: 2 | C12: العرض والطباعة والأتمتة | D12: 2 | E12: أي معاملة يتم طباعة إيصال لها مباشرة من المعاملة دون الحاجة إلى تصدير إلى إكسل، زي سند الصرف.
A13: 12 | B13: 2 | C13: العرض والطباعة والأتمتة | D13: 3 | E13: التقارير Automation — تحدث تلقائيًا بدون تدخل. على سبيل المثال تقرير يومي يتم تصديره بالمدفوعات والمقبوضات المستحقة خلال فترة زمنية (اليوم / أسبوع / شهر / ربع سنوي). | F13: Automation
A14: 13 | B14: 3 | C14: سندات الصرف والقبض | D14: ملاحظة | E14: ملاحظة في رأس الصفحة: ⟨إضافة خيار شيك مستبدل مع الاحتفاظ بالمعاملة — مع إضافة حالة مستبدل إلى مرسل أو غير مدفوع⟩. | G14: نعم
A15: 14 | B15: 3 | C15: سندات الصرف والقبض | D15: 1 | E15: عند تكرار الدفعات يكون الطرف ونوع الدفعة قابلة للتعديل.
A16: 15 | B16: 3 | C16: سندات الصرف والقبض | D16: 2 | E16: عند إلغاء الدفعة يتم إضافة خيار إلغاء الدفعة إلى قائمة الإجراءات، مع الاحتفاظ بالدفعة الملغية على السيستم وتلوينها باللون الأحمر.
A17: 16 | B17: 3 | C17: سندات الصرف والقبض | D17: 3 | E17: معالجة تطبيقات الدفع لتسمح بالدفع الجزئي، بحيث يظهر مبلغ المستحق للصرف والمبلغ المصروف فعليًا والمبلغ المتبقي.
A18: 17 | B18: 3 | C18: سندات الصرف والقبض | D18: 4 | E18: عمل شاشات لتعديل أو حذف مركز التكلفة.
A19: 18 | B19: 3 | C19: سندات الصرف والقبض | D19: 5 | E19: طريقة عرض الشاشات الرئيسية لكل سندات الصرف والقبض تحتاج إلى إعادة هيكلة لعرض جميع الأعمدة بدون التنقل يمينًا ويسارًا.
A20: 19 | B20: 3 | C20: سندات الصرف والقبض | D20: 6 | E20: طباعة الإيصالات محتاجة تعديل لتتم الطباعة بطريقة احترافية، وشكل الإيصال يكون كما النموذج المرسل إليك.
A21: 20 | B21: 3 | C21: سندات الصرف والقبض | D21: 7-أ | E21: مطلوب تقارير يومية — الحركات اليومية للخزينة النقدية: رصيد أول اليوم + الحركات المدينة / الحركات الدائنة = رصيد آخر اليوم. ★ إضافة عمود تاريخ إنشاء المعاملة + تاريخ الموافقة على المعاملة.
A22: 21 | B22: 3 | C22: سندات الصرف والقبض | D22: 7-ب | E22: مطلوب تقارير يومية — الحركات اليومية الإجمالية لكل موظف (Daily Activity Report) من أول login، مع إظهار المعاملات التي تم الموافقة عليها. | F22: Daily Activity Report
A23: 22 | B23: 3 | C23: سندات الصرف والقبض | D23: 8 | E23: إضافة شاشة للمعاملات التي تحتاج إلى موافقة في شاشة الصرف وشاشة القبض (Approval Q). | F23: Approval Q
A24: 23 | B24: 3 | C24: سندات الصرف والقبض | D24: 9 | E24: الفلاتر في الشاشة الرئيسية تحتاج المراجعة لإضافة Date range وإمكانية استخدام أكثر من فلتر، مع تفعيل الترتيب زي حالة الاستحقاق. | F24: Date range
A25: 24 | B25: 4 | C25: القيود اليومية | D25: 1 | E25: تقرير يومي بكل القيود التي تم تحريرها من قبل الموظف.
A26: 25 | B26: 4 | C26: القيود اليومية | D26: 2 | E26: الصلاحيات في القيود تكون زي سندات الصرف والقبض.
A27: 26 | B27: 4 | C27: القيود اليومية | D27: 3 | E27: طريقة عرض الشاشة الرئيسية المفروض تبين رقم الدفعة / الفاتورة لأي قيد يتم إنشاؤه تلقائيًا.
A28: 27 | B28: 4 | C28: الرواتب والسلف | D28: 1 | E28: إمكانية الترتيب والفلترة بالاسم أو القسم أو المبلغ، والبحث.
A29: 28 | B29: 4 | C29: الرواتب والسلف | D29: 2 | E29: إمكانية تعديل الفاتورة لموظف (لحدث تغيير في ⟨البيانات⟩ والقيود) بدلًا من حذف كل الموظفين وتحريرها مرة أخرى. | G29: نعم
A30: 29 | B30: 4 | C30: الرواتب والسلف | D30: 3 | E30: إضافة الرصيد ⟨المتقدم⟩ مع الإجازات والرصيد المستحق. | G30: نعم
A31: 30 | B31: 4 | C31: الرواتب والسلف | D31: 4 | E31: إمكانية تعديل السلف — مبلغ الاستقطاع الشهري — بعد الاتفاق.
A32: 31 | B32: 4 | C32: الرواتب والسلف | D32: 4-1 | E32: (بند فرعي تحت السلف) إمكانية وإضافة إعادة التعيين لتعديل أو زيادة بعد الاتفاق.
A33: 32 | B33: 4 | C33: الرواتب والسلف | D33: 4-2 | E33: (بند فرعي تحت السلف) عند الضغط على المبلغ ⟨المستحق⟩ يعرض ويطبع الحركات ⟨المستخدمة⟩ — كشف حساب. | G33: نعم
A34: 33 | B34: 4 | C34: ⟨السلف المقدمة⟩ | D34: 1 | E34: إمكانية عرض أرقام السندات ⟨المقدرة⟩ ومبالغها في شاشة سندات الصرف. | G34: نعم
A35: 34 | B35: 4 | C35: ⟨السلف المقدمة⟩ | D35: 2 | E35: Approval Q للمعاملات المطلوب الموافقة عليها. | F35: Approval Q | G35: نعم
A36: 35 | B36: 5 | C36: المبيعات | D36: 1 | E36: الدمج مع الواتس لإرسال رسائل مختلفة للعملاء بالأقساط المستحقة: تذكير بمواعيد الاستحقاق قبلها، ورسائل للأقساط المتأخرة أو ارتداد الشيكات. | F36: WhatsApp
A37: 36 | B37: 5 | C37: المبيعات | D37: 2 | E37: إمكانية تعديل بيانات في طلبات المبيعات دون حذف كل الدفعات السابقة، مثل تعديل التاريخ.
A38: 37 | B38: 5 | C38: المبيعات | D38: 3 | E38: الاحتفاظ بطلب المبيعات وإمكانية تغيير العميل أو تعديل الدفعات في حالة بيع الوحدة، أو زيادة مبلغ البيع في حالة زيادة المساحة مثل الروف بعد الحصول على ترخيص.
A39: 38 | B39: 5 | C39: المبيعات | D39: 4 | E39: إمكانية ومرونة تغيير الدفعات وإعادة هيكلتها، مع وجود إمكانية لدفعات مختلطة: شهرية + ربع سنوية + سنوية.
A40: 39 | B40: 5 | C40: المبيعات | D40: 5-أ | E40: ⟨بند هامشي⟩ إضافة المصاريف / الضرائب المحملة على المشروع إلى تقرير المشروع. | G40: نعم
...

Sheet مثال نسب الإنجاز
A1: المثال المكتوب بخط اليد في الصفحة ٦ — بند ٢ (نسب الإنجاز التراكمية)
A3: المبلغ التعاقدي | B3: المقاول | C3: نسبة الإنجاز الحالية | D3: المبلغ المستحق | E3: المدفوع | F3: المتبقي
A4: 10000 | B4: × | C4: 0.2 | D4: =A4*C4 | E4: 2000 | F4: =A4-E4
A5: 10000 | B5: × | C5: 0.3 | D5: =A5*C5
A7: كما كتبها العميل تحت الجدول:
A8: نسبة الإنجاز ← الحالية / السابقة / إجمالي نسبة الإنجاز (٪١٠ / ٪٢٠ / ٪٣٠)
A9: المبالغ ← الحالية / المدفوع سابقًا / المتبقي
A11: الأرقام بالأزرق منقولة من خط اليد؛ المستحق والمتبقي معادلات (المبلغ × النسبة، المبلغ − المدفوع). الصف الثاني لم يُستكمل في الأصل.

Sheet ملخص
A1: عدد البنود حسب القسم
A3: القسم | B3: عدد البنود | C3: منها قراءات غير مؤكدة
A4: التقارير والنظام عمومًا | B4: =COUNTIF('البنود'!$C$2:$C$49,A4) | C4: =COUNTIFS('البنود'!$C$2:$C$49,A4,'البنود'!$G$2:$G$49,"نعم")
A5: العرض والطباعة والأتمتة | B5: =COUNTIF('البنود'!$C$2:$C$49,A5) | C5: =COUNTIFS('البنود'!$C$2:$C$49,A5,'البنود'!$G$2:$G$49,"نعم")
A6: سندات الصرف والقبض | B6: =COUNTIF('البنود'!$C$2:$C$49,A6) | C6: =COUNTIFS('البنود'!$C$2:$C$49,A6,'البنود'!$G$2:$G$49,"نعم")
A7: القيود اليومية | B7: =COUNTIF('البنود'!$C$2:$C$49,A7) | C7: =COUNTIFS('البنود'!$C$2:$C$49,A7,'البنود'!$G$2:$G$49,"نعم")
A8: الرواتب والسلف | B8: =COUNTIF('البنود'!$C$2:$C$49,A8) | C8: =COUNTIFS('البنود'!$C$2:$C$49,A8,'البنود'!$G$2:$G$49,"نعم")
A9: ⟨السلف المقدمة⟩ | B9: =COUNTIF('البنود'!$C$2:$C$49,A9) | C9: =COUNTIFS('البنود'!$C$2:$C$49,A9,'البنود'!$G$2:$G$49,"نعم")
A10: المبيعات | B10: =COUNTIF('البنود'!$C$2:$C$49,A10) | C10: =COUNTIFS('البنود'!$C$2:$C$49,A10,'البنود'!$G$2:$G$49,"نعم")
A11: المستخلصات | B11: =COUNTIF('البنود'!$C$2:$C$49,A11) | C11: =COUNTIFS('البنود'!$C$2:$C$49,A11,'البنود'!$G$2:$G$49,"نعم")
A12: الإجمالي | B12: =SUM(B4:B11) | C12: =SUM(C4:C11)
A14: المصدر: 2nd phase ERP SYS updated.pdf (٦ صفحات بخط اليد، ٢٩ يوليو ٢٠٢٦) — منقول عبر 2nd-phase-ERP-SYS-transcription.md. القراءات غير المؤكدة مظللة بالأصفر في ورقة «البنود».
